Workbook

Sheet 작성기준
B2: KS X 9101-1 기업 확장(Extension) 정의서
B3: 기준: KS X 9101-1:2025 개정(안) v1.0 테이블 정의서와 같은 양식 · 구현안내서 5.6(Core/Extension 판정), 7장(S4 생성) · 이 파일이 ksxgen의 Extension 입력이다(extensions/{기업}/확장정의서.xlsx)
B5: 작성 단계
B6: S1 원천 분석 | C6: 원천 공백·Extension 후보를 찾는다(인벤토리·시나리오 정의서·KPI 정의서의 '공백·Extension')
B7: S2 표준 매핑 | C7: 후보마다 5.6 규칙으로 판정해 이 파일에 적고 현업 승인을 받는다(판정목록 → 테이블목록·테이블정의서·공통코드)
B8: S4 T-Box 생성 | C8: ksxgen build --ext extensions/{기업} → Extension T-Box·SHACL·OBDA·DDL·코드 목록 생성(Core는 수정하지 않음)
B10: 구성
B11: 테이블목록 | C11: 확장 명사·확장 속성 테이블 목록. 표준 열(No~물리 FK 수) + 확장 열(확장유형, 대상 Core 명사, 판정 규칙, 원천, 관련 시나리오·KPI, 상태)
B12: 테이블정의서 | C12: 확장 테이블의 컬럼. 표준과 같은 열. 구분 = PK / 기본 / Core키 / 확장
B13: 관계목록 | C13: 자동 생성(ext-sync). FK 참조 열에서 도출
B14: 코드그룹목록·공통코드 | C14: 확장 코드 그룹과 코드. 표준 공통코드 워크시트와 같은 열. '회사 코드값'은 원천 코드(대응표 겸용)
B15: 판정목록 | C15: S1 후보 → 5.6 판정 기록(표준 매핑·코드 대응·확장·제외·S3 처리). 확장이 아닌 판정도 근거와 함께 남긴다
B16: 검토·승인 | C16: ksxgen 검사 결과와 승인 서명
B17: DDL | C17: 자동 생성(ext-sync). ext 스키마 CREATE TABLE 참고 스크립트
B19: 판정 규칙(5.6)
B20: ① 표준 매핑 | C20: 표준 속성과 의미·타입이 같다 → 확장하지 않는다(매핑 명세에 기록)
B21: ② 확장 속성 | C21: 표준 명사에 속하지만 표준 속성에 없다 → 확장유형 '확장 속성': ext 스키마 1:1 테이블({명사}Ext), Core UK 참조
B22: ③ 확장 명사 | C22: 표준 명사로 표현할 수 없는 업무 객체 → 확장유형 '확장 명사': ID 식별, 기본 속성 3종, 참조 대상 명시
B23: ④ 제외 | C23: 분석·운영에 쓰지 않는 기술 컬럼 → 제외(판정목록에 사유)
B24: 코드 | C24: 표준 그룹 코드로 대응되면 '코드 대응'(확장 아님). 회사정의(계층) 그룹에 하위 코드를 더하면 '표준 그룹 하위 확장', 표준에 없는 그룹은 '신규 그룹'
B26: 작성 방법
B27: 테이블목록 | C27: 확장유형·테이블명(국문·영문)·업무영역·설명·UK(확장 명사)·대상 Core 명사(확장 속성)만 적는다. 확장 속성 테이블의 영문명은 {대상 Core 명사}Ext, UK는 비워 두면 Core UK로 채운다
B28: 테이블정의서 | C28: 업무 속성(구분 '확장')만 적어도 된다. PK·기본 속성 8종(확장 명사)·Core키(확장 속성) 행은 ext-sync가 채운다
B29: 데이터 타입 | C29: ID · IDREF · enum · string · int · float · date · dateTime · boolean · duration (물리 타입은 비워 두면 권장값)
B30: IDREF | C30: FK 참조(테이블.컬럼)에 부모 테이블의 UK 컬럼을 적는다(예: ItemMaster.ItemID). 부모 UK가 복합이면 컬럼마다 적는다
B31: enum | C31: 코드 참조에 CommonCodeGroup=그룹(표준·확장 그룹) 또는 단위그룹(UOMGroup).UOMCode
B32: 이름 | C32: 표준 속성과 같은 영문명은 같은 의미·타입일 때만 쓴다(그대로 공유 속성 ksx:… 재사용). 새 이름은 기업 네임스페이스로 생성
B33: 상태 | C33: 초안 → 검토 → 승인. '후보'는 원천이 아직 없는 항목, '예시'는 생성기가 무시
B35: 금지(빌드 실패)
B36: Core 수정 | C36: 표준 명사·속성·코드의 삭제·재정의, 표준 속성과 같은 이름에 다른 타입, 표준 테이블명·코드 그룹명 재사용(하위 확장 제외)
B37: 이름 공간 | C37: ksx: 이름 추가 금지 — 확장 이름은 기업 네임스페이스(extensions/{기업}/ext.yaml의 prefix·ns)에 만든다
B38: 공리 | C38: Core 클래스에 대한 동치·배타 선언, Core 속성 domain/range 재정의 금지
B40: 명령
B41: 양식 | C41: python -m ksxgen ext-template --out extensions/{기업}/확장정의서.xlsx
B42: 채움·검사 | C42: python -m ksxgen ext-sync extensions/{기업}/확장정의서.xlsx --std standards
B43: 생성 | C43: python -m ksxgen build --std standards --ext extensions/{기업} --out ontologies

Sheet 테이블목록
A1: No | B1: 업무영역 | C1: 조항 | D1: 표 | E1: 테이블명(국문) | F1: 테이블명(영문) | G1: 물리 테이블명 | H1: 테이블 설명(표준 정의) | I1: PK | J1: UK(식별 키) | K1: UK 근거 | L1: UK 비고 | M1: 컬럼 수 | N1: 기본 속성 수 | O1: 물리 FK 수 | P1: 확장유형 | Q1: 대상 Core 명사 | R1: 판정 규칙(5.6) | S1: 원천(시스템.테이블) | T1: 관련 시나리오·KPI·질의 | U1: 상태
A2: 1 | B2: 원가관리(확장) | C2: 확장 | E2: 표준원가 | F2: StandardCost | G2: StandardCost | H2: 품목(필요 시 공정 단계)의 원가 기간별 표준원가와 원가 요소를 의미한다. 재공·불량·재고 금액 환산의 기준이 된다. | I2: StandardCostSequenceNo | J2: EnterpriseID + StandardCostID | K2: 확장 ID | L2: 업무 키: 품목 + 공정(선택) + 원가기간 시작일. 식별자 규칙 예: HSG-A100_P200_202610 | M2: =COUNTIF(테이블정의서!$A$2:$A$145,F2) | N2: =COUNTIFS(테이블정의서!$A$2:$A$145,F2,테이블정의서!$H$2:$H$145,"기본") | O2: =COUNTIFS(관계목록!$B$2:$B$48,F2,관계목록!$H$2:$H$48,"물리") | P2: 확장 명사 | R2: ③ 확장 명사 | S2: erp.tb_co_std_cost, qms.qm_scrap.unit_cost | T2: SC02·SC05·SC06·SC07 / PR02·PR04·QM04·QM07·SC06·SC07·SC09 | U2: 초안
A3: 2 | B3: 품질관리(확장) | C3: 확장 | E3: 고객클레임 | F3: CustomerComplaint | G3: CustomerComplaint | H3: 고객이 제기한 제품 부적합(입고검사 부적합·라인 중단·필드 반송)과 대책 회신·종결 이력을 의미한다. | I3: CustomerComplaintSequenceNo | J3: EnterpriseID + CustomerComplaintID | K3: 확장 ID | M3: =COUNTIF(테이블정의서!$A$2:$A$145,F3) | N3: =COUNTIFS(테이블정의서!$A$2:$A$145,F3,테이블정의서!$H$2:$H$145,"기본") | O3: =COUNTIFS(관계목록!$B$2:$B$48,F3,관계목록!$H$2:$H$48,"물리") | P3: 확장 명사 | R3: ③ 확장 명사 | S3: qms.qm_claim | T3: SC06 / QM01·QM02·QM03·QM04·QM07 / Q-SC06-01~06 | U3: 초안
A4: 3 | B4: 품질관리(확장) | C4: 확장 | E4: 품질비용 | F4: QualityCost | G4: QualityCost | H4: 원가 기간별 품질비용(Q-COST)을 예방·평가·내부실패·외부실패 구분과 비용 항목으로 집계한 값을 의미한다. | I4: QualityCostSequenceNo | J4: EnterpriseID + QualityCostID | K4: 확장 ID | L4: 업무 키: 공장 + 원가기간 + 비용 항목 | M4: =COUNTIF(테이블정의서!$A$2:$A$145,F4) | N4: =COUNTIFS(테이블정의서!$A$2:$A$145,F4,테이블정의서!$H$2:$H$145,"기본") | O4: =COUNTIFS(관계목록!$B$2:$B$48,F4,관계목록!$H$2:$H$48,"물리") | P4: 확장 명사 | R4: ③ 확장 명사 | S4: qms.qm_qcost | T4: SC06 / PR05·QM04 / Q-SC06-07~10 | U4: 초안
A5: 4 | B5: 재고관리(확장) | C5: 확장 | E5: 일별재고 | F5: InventorySnapshot | G5: InventorySnapshot | H5: 기준일 마감 시점의 창고·품목별 재고수량을 의미한다. 표준 재고(Inventory)는 현재고만 정의하므로 기준일 이력을 별도로 둔다. | I5: InventorySnapshotSequenceNo | J5: EnterpriseID + InventorySnapshotDate + WarehouseID + ItemID | K5: 조합(제안) | L5: 재고(Inventory, 표 68)의 식별 조합 + 기준일. 표준 재고와 같은 의미의 시점 이력 | M5: =COUNTIF(테이블정의서!$A$2:$A$145,F5) | N5: =COUNTIFS(테이블정의서!$A$2:$A$145,F5,테이블정의서!$H$2:$H$145,"기본") | O5: =COUNTIFS(관계목록!$B$2:$B$48,F5,관계목록!$H$2:$H$48,"물리") | P5: 확장 명사 | R5: ③ 확장 명사 | S5: erp.tb_mm_stock_day | T5: SC07 / SC06·SC07·CS02 / Q-SC07-07·08·14 | U5: 초안
A6: 5 | B6: 재고관리(확장) | C6: 확장 | E6: 로트별재고 | F6: LotInventory | G6: LotInventory | H6: 창고·품목의 현재고를 로트와 입고일 단위로 나눈 재고를 의미한다. 재고 경과일(장기 체화)·선입선출 판단의 근거가 된다. | I6: LotInventorySequenceNo | J6: EnterpriseID + WarehouseID + ItemID + LotID | K6: 조합(제안) | L6: 재고(Inventory)의 식별 조합 + 로트 | M6: =COUNTIF(테이블정의서!$A$2:$A$145,F6) | N6: =COUNTIFS(테이블정의서!$A$2:$A$145,F6,테이블정의서!$H$2:$H$145,"기본") | O6: =COUNTIFS(관계목록!$B$2:$B$48,F6,관계목록!$H$2:$H$48,"물리") | P6: 확장 명사 | R6: ③ 확장 명사 | S6: erp.tb_mm_stock_lot | T6: SC07 / SC09 / Q-SC07-11·12 | U6: 초안
A7: 6 | B7: 판매관리 | C7: 확장 | E7: 판매계획 확장 | F7: SalesPlanExt | G7: SalesPlanExt | H7: 판매계획(SalesPlan)에 계획 유형(수요예측·판매계획)·고객·버전을 더한다. | I7: SalesPlanExtSequenceNo | J7: EnterpriseID + SalesPlanID | K7: Core UK | M7: =COUNTIF(테이블정의서!$A$2:$A$145,F7) | N7: =COUNTIFS(테이블정의서!$A$2:$A$145,F7,테이블정의서!$H$2:$H$145,"기본") | O7: =COUNTIFS(관계목록!$B$2:$B$48,F7,관계목록!$H$2:$H$48,"물리") | P7: 확장 속성 | Q7: SalesPlan | R7: ② 확장 속성 | S7: erp.tb_sd_plan | T7: SC07 / SC01·SC02 / Q-SC07-01~03 | U7: 초안
A8: 7 | B8: 판매관리 | C8: 확장 | E8: 수주오더라인 확장 | F8: SalesOrderLineExt | G8: SalesOrderLineExt | H8: 수주오더라인에 판매단가·통화·판매금액을 더한다(매출액·Q-COST 매출 대비 비율). | I8: SalesOrderLineExtSequenceNo | J8: EnterpriseID + SalesDocumentNumber + SalesDocumentSequence | K8: Core UK | M8: =COUNTIF(테이블정의서!$A$2:$A$145,F8) | N8: =COUNTIFS(테이블정의서!$A$2:$A$145,F8,테이블정의서!$H$2:$H$145,"기본") | O8: =COUNTIFS(관계목록!$B$2:$B$48,F8,관계목록!$H$2:$H$48,"물리") | P8: 확장 속성 | Q8: SalesOrderLine | R8: ② 확장 속성 | S8: erp.tb_sd_so_d | T8: SC07·SC06 / QM04 / Q-SC07-19 | U8: 초안
A9: 8 | B9: 재고관리 | C9: 확장 | E9: 가용재고 확장 | F9: AvailableInventoryExt | G9: AvailableInventoryExt | H9: 가용재고(자재 가용성 점검)에 대상 생산지시·점검 일시·부족 수량을 더한다. | I9: AvailableInventoryExtSequenceNo | J9: EnterpriseID + AvailableInventoryID | K9: Core UK | M9: =COUNTIF(테이블정의서!$A$2:$A$145,F9) | N9: =COUNTIFS(테이블정의서!$A$2:$A$145,F9,테이블정의서!$H$2:$H$145,"기본") | O9: =COUNTIFS(관계목록!$B$2:$B$48,F9,관계목록!$H$2:$H$48,"물리") | P9: 확장 속성 | Q9: AvailableInventory | R9: ② 확장 속성 | S9: erp.tb_pp_mat_chk | T9: SC07 / SC04 / Q-SC07-05·06 | U9: 초안
A10: 9 | B10: 생산관리 | C10: 확장 | E10: 생산실적 확장 | F10: ProductionPerformanceExt | G10: ProductionPerformanceExt | H10: 생산실적(공정 실적)에 검사 판정과 검사 수량을 더한다. | I10: ProductionPerformanceExtSequenceNo | J10: EnterpriseID + ProductionPerformanceID + ProductionPerformanceSequence | K10: Core UK | M10: =COUNTIF(테이블정의서!$A$2:$A$145,F10) | N10: =COUNTIFS(테이블정의서!$A$2:$A$145,F10,테이블정의서!$H$2:$H$145,"기본") | O10: =COUNTIFS(관계목록!$B$2:$B$48,F10,관계목록!$H$2:$H$48,"물리") | P10: 확장 속성 | Q10: ProductionPerformance | R10: ② 확장 속성 | S10: mes.tb_qc_insp | T10: SC05 / QM05·PR03 / Q-SC05-07·12 | U10: 초안
A11: 10 | B11: 생산관리 | C11: 확장 | E11: 협력업체품질검사결과 확장 | F11: SupplierInspectionResultExt | G11: SupplierInspectionResultExt | H11: 협력업체 품질검사(수입검사) 결과에 입고 건 연결·불량 수량·불량 유형을 더한다. | I11: SupplierInspectionResultExtSequenceNo | J11: EnterpriseID + InspectionResultID | K11: Core UK | M11: =COUNTIF(테이블정의서!$A$2:$A$145,F11) | N11: =COUNTIFS(테이블정의서!$A$2:$A$145,F11,테이블정의서!$H$2:$H$145,"기본") | O11: =COUNTIFS(관계목록!$B$2:$B$48,F11,관계목록!$H$2:$H$48,"물리") | P11: 확장 속성 | Q11: SupplierInspectionResult | R11: ② 확장 속성 | S11: qms.qm_iqc | T11: SC06 / QM09 / Q-SC06-14·15 | U11: 초안
A12: 11 | B12: 생산관리 | C12: 확장 | E12: 시정조치요청 확장 | F12: CorrectiveActionRequestExt | G12: CorrectiveActionRequestExt | H12: 시정조치요청(협력업체 부적합)에 발견 위치·불량 수량·불량 유형·조치 기한을 더한다. | I12: CorrectiveActionRequestExtSequenceNo | J12: EnterpriseID + CorrectiveActionRequestID | K12: Core UK | M12: =COUNTIF(테이블정의서!$A$2:$A$145,F12) | N12: =COUNTIFS(테이블정의서!$A$2:$A$145,F12,테이블정의서!$H$2:$H$145,"기본") | O12: =COUNTIFS(관계목록!$B$2:$B$48,F12,관계목록!$H$2:$H$48,"물리") | P12: 확장 속성 | Q12: CorrectiveActionRequest | R12: ② 확장 속성 | S12: qms.qm_vend_ncr | T12: SC06 / QM08 / Q-SC06-12·13·17·19 | U12: 초안
A13: 12 | B13: 기준정보 | C13: 확장 | E13: 설비 확장 | F13: EquipmentExt | G13: EquipmentExt | H13: 설비에 설비별 표준 분당 생산수량(UPM)을 더한다(현재는 공정 표준시간으로 대체). | I13: EquipmentExtSequenceNo | J13: EnterpriseID + EquipmentID | K13: Core UK | M13: =COUNTIF(테이블정의서!$A$2:$A$145,F13) | N13: =COUNTIFS(테이블정의서!$A$2:$A$145,F13,테이블정의서!$H$2:$H$145,"기본") | O13: =COUNTIFS(관계목록!$B$2:$B$48,F13,관계목록!$H$2:$H$48,"물리") | P13: 확장 속성 | Q13: Equipment | R13: ② 확장 속성 | S13: (원천 없음 — 설비 기준정보 보완) | T13: SC04 / EQ01·EQ07 | U13: 후보
A14: 13 | B14: 생산관리 | C14: 확장 | E14: 설비상태 확장 | F14: EquipmentStateExt | G14: EquipmentStateExt | H14: 설비상태(대기)에 대기 사유를 더해 대기를 작업 없음·자재 부족 등으로 나눈다. | I14: EquipmentStateExtSequenceNo | J14: EnterpriseID + EquipmentStateID | K14: Core UK | M14: =COUNTIF(테이블정의서!$A$2:$A$145,F14) | N14: =COUNTIFS(테이블정의서!$A$2:$A$145,F14,테이블정의서!$H$2:$H$145,"기본") | O14: =COUNTIFS(관계목록!$B$2:$B$48,F14,관계목록!$H$2:$H$48,"물리") | P14: 확장 속성 | Q14: EquipmentState | R14: ② 확장 속성 | S14: (원천 없음 — MES 개선) | T14: SC04 / EQ06 | U14: 후보

Sheet 테이블정의서
A1: 테이블명(영문) | B1: 테이블명(국문) | C1: 물리 테이블명 | D1: 순번 | E1: 속성명(국문) | F1: 컬럼명(영문) | G1: 물리 컬럼명 | H1: 구분 | I1: 데이터 타입(표준) | J1: 물리 타입(권장) | K1: PK | L1: UK | M1: FK | N1: NOT NULL | O1: FK 참조(테이블.컬럼) | P1: 참조속성 대상여부 | Q1: 코드 참조 | R1: 설명 | S1: 원천(시스템.테이블.컬럼) | T1: 근거(시나리오·KPI·질의) | U1: 상태
A2: StandardCost | B2: 표준원가 | C2: StandardCost | D2: 1 | E2: 표준원가 일련번호 | F2: StandardCostSequenceNo | G2: StandardCostSequenceNo | H2: PK | I2: bigint | J2: BIGINT | K2: Y | N2: Y | P2: 비대상 | R2: — 테이블 행을 식별하는 일련번호(PK, 대리키) — 표준 외 물리 컬럼 — 자동 증가 값(IDENTITY)으로 부여하며 다른 테이블이 참조하지 않음(FK는 UK 참조) | U2: 자동
A3: StandardCost | B3: 표준원가 | C3: StandardCost | D3: 2 | E3: 회사식별자 | F3: EnterpriseID | G3: EnterpriseID | H3: 기본 | I3: IDREF | J3: VARCHAR(50) | L3: UK | M3: Y | N3: Y | O3: Enterprise.EnterpriseID | P3: 대상 | R3: — 회사를 유일하게 구분할 수 있는 고유식별값 — 기업업무시스템 간의 연동을 수행하는 회사들 간에 자체적으로 정의한 고유식별값 — 참조 대상: 회사(Enterprise) | U3: 자동
A4: StandardCost | B4: 표준원가 | C4: StandardCost | D4: 3 | E4: 사업장식별자 | F4: SiteID | G4: SiteID | H4: 기본 | I4: IDREF | J4: VARCHAR(50) | M4: Y | N4: Y | O4: Site.SiteID | P4: 대상 | R4: — 회사 내에서 사업장을 구분할수 있는 고유식별값 — 참조 대상: 사업장(Site) | U4: 자동
A5: StandardCost | B5: 표준원가 | C5: StandardCost | D5: 4 | E5: 공장식별자 | F5: PlantID | G5: PlantID | H5: 기본 | I5: IDREF | J5: VARCHAR(50) | M5: Y | N5: Y | O5: Plant.PlantID | P5: 대상 | R5: — 회사 내에서 공장을 구분할 수있는 고유식별값(만약, 공장 개념을 사용하지 않는다면 고정식별자로 설정하여 입력해야 함) — 참조 대상: 공장(Plant) | U5: 자동
A6: StandardCost | B6: 표준원가 | C6: StandardCost | D6: 5 | E6: 등록자식별자 | F6: CreatorID | G6: CreatorID | H6: 기본 | I6: IDREF | J6: VARCHAR(50) | M6: Y | O6: Personnel.PersonnelID | P6: 대상 | R6: — 정보를 처음으로 등록한 사람을 구분할 수 있는 고유식별값으로, 일반적으로 사원번호가사용됨 — 참조 대상: 사원(Personnel) | U6: 자동
A7: StandardCost | B7: 표준원가 | C7: StandardCost | D7: 6 | E7: 등록일시 | F7: CreationDateTime | G7: CreationDateTime | H7: 기본 | I7: dateTime | J7: TIMESTAMP | P7: 비대상 | R7: — 정보를 처음으로 등록한 날짜 (KS X ISO 8601을 따른다) | U7: 자동
A8: StandardCost | B8: 표준원가 | C8: StandardCost | D8: 7 | E8: 수정자식별자 | F8: ModifierID | G8: ModifierID | H8: 기본 | I8: IDREF | J8: VARCHAR(50) | M8: Y | O8: Personnel.PersonnelID | P8: 대상 | R8: — 정보를 마지막으로 수정한 사람을 구분할 수 있는 고유식별값으로, 일반적으로 사원번호가 사용됨 — 참조 대상: 사원(Personnel) | U8: 자동
A9: StandardCost | B9: 표준원가 | C9: StandardCost | D9: 8 | E9: 수정일시 | F9: ModificationDateTime | G9: ModificationDateTime | H9: 기본 | I9: dateTime | J9: TIMESTAMP | P9: 비대상 | R9: — 정보를 마지막으로 수정한 날짜 (KS X ISO 8601을 따른다.) | U9: 자동
A10: StandardCost | B10: 표준원가 | C10: StandardCost | D10: 9 | E10: 비고 | F10: Note | G10: Note | H10: 기본 | I10: string | J10: VARCHAR(1000) | P10: 비대상 | R10: — 비고사항 | U10: 자동
A11: StandardCost | B11: 표준원가 | C11: StandardCost | D11: 10 | E11: 표준원가식별자 | F11: StandardCostID | G11: StandardCostID | H11: 확장 | I11: ID | J11: VARCHAR(50) | L11: UK | N11: Y | P11: 비대상 | R11: — 표준원가 행을 식별하는 고유값(품목·공정·원가기간 조합에 회사가 부여) | S11: erp.tb_co_std_cost.(item_cd, cost_ym) | T11: PR02 재공 금액, SC06 재고 금액 | U11: 초안
A12: StandardCost | B12: 표준원가 | C12: StandardCost | D12: 11 | E12: 품목식별자 | F12: ItemID | G12: ItemID | H12: 확장 | I12: IDREF | J12: VARCHAR(50) | M12: Y | N12: Y | O12: ItemMaster.ItemID | P12: 대상 | R12: — 원가 대상 품목 — 참조 대상: 품목마스터(ItemMaster) | S12: erp.tb_co_std_cost.item_cd | U12: 초안
A13: StandardCost | B13: 표준원가 | C13: StandardCost | D13: 12 | E13: 공정식별자 | F13: OperationID | G13: OperationID | H13: 확장 | I13: IDREF | J13: VARCHAR(50) | M13: Y | O13: Operation.OperationID | P13: 대상 | R13: — 공정 단계 누적원가의 공정. 비우면 품목 완성 원가 — 참조 대상: 공정(Operation) | S13: qms.qm_scrap.proc_cd | T13: PR04 공정별 불량금액(공정 단계 원가) | U13: 초안
A14: StandardCost | B14: 표준원가 | C14: StandardCost | D14: 13 | E14: 원가기간시작일 | F14: CostPeriodStartDate | G14: CostPeriodStartDate | H14: 확장 | I14: date | J14: DATE | N14: Y | P14: 비대상 | R14: — 표준원가 적용 시작일(KS X ISO 8601) | S14: erp.tb_co_std_cost.cost_ym(월 첫날) | U14: 초안
A15: StandardCost | B15: 표준원가 | C15: StandardCost | D15: 14 | E15: 원가기간종료일 | F15: CostPeriodEndDate | G15: CostPeriodEndDate | H15: 확장 | I15: date | J15: DATE | P15: 비대상 | R15: — 표준원가 적용 종료일(KS X ISO 8601) | S15: erp.tb_co_std_cost.cost_ym(월 말일) | U15: 초안
A16: StandardCost | B16: 표준원가 | C16: StandardCost | D16: 15 | E16: 표준원가 | F16: StandardCostAmount | G16: StandardCostAmount | H16: 확장 | I16: float | J16: NUMERIC(18,6) | N16: Y | P16: 비대상 | R16: — 기준단위 1개당 표준원가(재료비+노무비+경비) | S16: erp.tb_co_std_cost.std_cost / qms.qm_scrap.unit_cost | U16: 초안
A17: StandardCost | B17: 표준원가 | C17: StandardCost | D17: 16 | E17: 재료비 | F17: MaterialCostAmount | G17: MaterialCostAmount | H17: 확장 | I17: float | J17: NUMERIC(18,6) | P17: 비대상 | R17: — 표준원가 중 재료비 | S17: erp.tb_co_std_cost.mat_cost | U17: 초안
A18: StandardCost | B18: 표준원가 | C18: StandardCost | D18: 17 | E18: 노무비 | F18: LaborCostAmount | G18: LaborCostAmount | H18: 확장 | I18: float | J18: NUMERIC(18,6) | P18: 비대상 | R18: — 표준원가 중 노무비 | S18: erp.tb_co_std_cost.lab_cost | U18: 초안
A19: StandardCost | B19: 표준원가 | C19: StandardCost | D19: 18 | E19: 경비 | F19: OverheadCostAmount | G19: OverheadCostAmount | H19: 확장 | I19: float | J19: NUMERIC(18,6) | P19: 비대상 | R19: — 표준원가 중 경비 | S19: erp.tb_co_std_cost.ovh_cost | U19: 초안
A20: StandardCost | B20: 표준원가 | C20: StandardCost | D20: 19 | E20: 환종코드 | F20: CurrencyCode | G20: CurrencyCode | H20: 확장 | I20: enum | J20: VARCHAR(30) | P20: 대상 | Q20: CommonCodeGroup=CurrencyCode | R20: — 원가 금액의 통화(ISO 4217) — 참조 대상: 공통코드정보(CommonCodeMaster)의 코드 | S20: erp.tb_co_std_cost.curr_cd | U20: 초안
A21: StandardCost | B21: 표준원가 | C21: StandardCost | D21: 20 | E21: 기준단위코드 | F21: ItemUOMCode | G21: ItemUOMCode | H21: 확장 | I21: enum | J21: VARCHAR(30) | P21: 대상 | Q21: 단위그룹(UOMGroup).UOMCode | R21: — 원가 수량의 기준단위 — 참조 대상: 단위그룹(UOMGroup)의 단위코드 | S21: erp.tb_mm_item.unit | U21: 초안
A22: CustomerComplaint | B22: 고객클레임 | C22: CustomerComplaint | D22: 1 | E22: 고객클레임 일련번호 | F22: CustomerComplaintSequenceNo | G22: CustomerComplaintSequenceNo | H22: PK | I22: bigint | J22: BIGINT | K22: Y | N22: Y | P22: 비대상 | R22: — 테이블 행을 식별하는 일련번호(PK, 대리키) — 표준 외 물리 컬럼 — 자동 증가 값(IDENTITY)으로 부여하며 다른 테이블이 참조하지 않음(FK는 UK 참조) | U22: 자동
A23: CustomerComplaint | B23: 고객클레임 | C23: CustomerComplaint | D23: 2 | E23: 회사식별자 | F23: EnterpriseID | G23: EnterpriseID | H23: 기본 | I23: IDREF | J23: VARCHAR(50) | L23: UK | M23: Y | N23: Y | O23: Enterprise.EnterpriseID | P23: 대상 | R23: — 회사를 유일하게 구분할 수 있는 고유식별값 — 기업업무시스템 간의 연동을 수행하는 회사들 간에 자체적으로 정의한 고유식별값 — 참조 대상: 회사(Enterprise) | U23: 자동
A24: CustomerComplaint | B24: 고객클레임 | C24: CustomerComplaint | D24: 3 | E24: 사업장식별자 | F24: SiteID | G24: SiteID | H24: 기본 | I24: IDREF | J24: VARCHAR(50) | M24: Y | N24: Y | O24: Site.SiteID | P24: 대상 | R24: — 회사 내에서 사업장을 구분할수 있는 고유식별값 — 참조 대상: 사업장(Site) | U24: 자동
A25: CustomerComplaint | B25: 고객클레임 | C25: CustomerComplaint | D25: 4 | E25: 공장식별자 | F25: PlantID | G25: PlantID | H25: 기본 | I25: IDREF | J25: VARCHAR(50) | M25: Y | N25: Y | O25: Plant.PlantID | P25: 대상 | R25: — 회사 내에서 공장을 구분할 수있는 고유식별값(만약, 공장 개념을 사용하지 않는다면 고정식별자로 설정하여 입력해야 함) — 참조 대상: 공장(Plant) | U25: 자동
A26: CustomerComplaint | B26: 고객클레임 | C26: CustomerComplaint | D26: 5 | E26: 등록자식별자 | F26: CreatorID | G26: CreatorID | H26: 기본 | I26: IDREF | J26: VARCHAR(50) | M26: Y | O26: Personnel.PersonnelID | P26: 대상 | R26: — 정보를 처음으로 등록한 사람을 구분할 수 있는 고유식별값으로, 일반적으로 사원번호가사용됨 — 참조 대상: 사원(Personnel) | U26: 자동
A27: CustomerComplaint | B27: 고객클레임 | C27: CustomerComplaint | D27: 6 | E27: 등록일시 | F27: CreationDateTime | G27: CreationDateTime | H27: 기본 | I27: dateTime | J27: TIMESTAMP | P27: 비대상 | R27: — 정보를 처음으로 등록한 날짜 (KS X ISO 8601을 따른다) | U27: 자동
A28: CustomerComplaint | B28: 고객클레임 | C28: CustomerComplaint | D28: 7 | E28: 수정자식별자 | F28: ModifierID | G28: ModifierID | H28: 기본 | I28: IDREF | J28: VARCHAR(50) | M28: Y | O28: Personnel.PersonnelID | P28: 대상 | R28: — 정보를 마지막으로 수정한 사람을 구분할 수 있는 고유식별값으로, 일반적으로 사원번호가 사용됨 — 참조 대상: 사원(Personnel) | U28: 자동
A29: CustomerComplaint | B29: 고객클레임 | C29: CustomerComplaint | D29: 8 | E29: 수정일시 | F29: ModificationDateTime | G29: ModificationDateTime | H29: 기본 | I29: dateTime | J29: TIMESTAMP | P29: 비대상 | R29: — 정보를 마지막으로 수정한 날짜 (KS X ISO 8601을 따른다.) | U29: 자동
A30: CustomerComplaint | B30: 고객클레임 | C30: CustomerComplaint | D30: 9 | E30: 비고 | F30: Note | G30: Note | H30: 기본 | I30: string | J30: VARCHAR(1000) | P30: 비대상 | R30: — 비고사항 | U30: 자동
A31: CustomerComplaint | B31: 고객클레임 | C31: CustomerComplaint | D31: 10 | E31: 고객클레임식별자 | F31: CustomerComplaintID | G31: CustomerComplaintID | H31: 확장 | I31: ID | J31: VARCHAR(50) | L31: UK | N31: Y | P31: 비대상 | R31: — 고객 클레임을 식별하는 고유값 | S31: qms.qm_claim.claim_no | U31: 초안
A32: CustomerComplaint | B32: 고객클레임 | C32: CustomerComplaint | D32: 11 | E32: 고객사식별자 | F32: CustomerID | G32: CustomerID | H32: 확장 | I32: IDREF | J32: VARCHAR(50) | M32: Y | N32: Y | O32: CustomerPartyMaster.CustomerID | P32: 대상 | R32: — 클레임을 제기한 고객사 — 참조 대상: 고객사(CustomerPartyMaster) | S32: qms.qm_claim.cust_cd | U32: 초안
A33: CustomerComplaint | B33: 고객클레임 | C33: CustomerComplaint | D33: 12 | E33: 품목식별자 | F33: ItemID | G33: ItemID | H33: 확장 | I33: IDREF | J33: VARCHAR(50) | M33: Y | O33: ItemMaster.ItemID | P33: 대상 | R33: — 클레임 대상 품목 — 참조 대상: 품목마스터(ItemMaster) | S33: qms.qm_claim.item_cd | U33: 초안
A34: CustomerComplaint | B34: 고객클레임 | C34: CustomerComplaint | D34: 13 | E34: 로트식별자 | F34: LotID | G34: LotID | H34: 확장 | I34: IDREF | J34: VARCHAR(50) | M34: Y | O34: Lot.LotID | P34: 대상 | R34: — 클레임 대상 출하 로트(추적 시작점) — 참조 대상: 로트(Lot) — MES 도입 전 로트는 S3에서 로트로 생성 후 연결 | S34: qms.qm_claim.lot_no | T34: Q-SC06-03 LOT 추적, QM03 | U34: 초안
A35: CustomerComplaint | B35: 고객클레임 | C35: CustomerComplaint | D35: 14 | E35: 고객클레임유형 | F35: CustomerComplaintType | G35: CustomerComplaintType | H35: 확장 | I35: enum | J35: VARCHAR(30) | N35: Y | P35: 대상 | Q35: CommonCodeGroup=CustomerComplaintType | R35: — 고객 부적합(NC)·고객 라인 중단(LS)·필드 반송(FR) — 참조 대상: 공통코드정보(CommonCodeMaster)의 코드 | S35: qms.qm_claim.claim_tp | T35: QM03 라인 중단·필드 반송 건수 | U35: 초안
A36: CustomerComplaint | B36: 고객클레임 | C36: CustomerComplaint | D36: 15 | E36: 발생일 | F36: OccurrenceDate | G36: OccurrenceDate | H36: 확장 | I36: date | J36: DATE | P36: 비대상 | R36: — 고객에서 부적합이 발생한 날(KS X ISO 8601) | S36: qms.qm_claim.occur_dt | U36: 초안
A37: CustomerComplaint | B37: 고객클레임 | C37: CustomerComplaint | D37: 16 | E37: 접수일 | F37: ComplaintReceiptDate | G37: ComplaintReceiptDate | H37: 확장 | I37: date | J37: DATE | P37: 비대상 | R37: — 회사가 클레임을 접수한 날(KS X ISO 8601) | S37: qms.qm_claim.rcv_dt | U37: 초안
A38: CustomerComplaint | B38: 고객클레임 | C38: CustomerComplaint | D38: 17 | E38: 불량유형코드 | F38: DefectTypeCode | G38: DefectTypeCode | H38: 확장 | I38: enum | J38: VARCHAR(30) | P38: 대상 | Q38: CommonCodeGroup=DefectTypeCode | R38: — 고객 불량 현상의 대분류 — 참조 대상: 공통코드정보(CommonCodeMaster)의 코드 | S38: qms.qm_claim.defect_cd(코드 대응) | U38: 초안
A39: CustomerComplaint | B39: 고객클레임 | C39: CustomerComplaint | D39: 18 | E39: 불량유형상세코드 | F39: DefectTypeDetailCode | G39: DefectTypeDetailCode | H39: 확장 | I39: enum | J39: VARCHAR(30) | P39: 대상 | Q39: CommonCodeGroup=DefectTypeDetailCode | R39: — 고객 불량 현상의 상세 코드(C-LEAK → FUNC-LEK 등 코드 대응) — 참조 대상: 공통코드정보(CommonCodeMaster)의 코드 | S39: qms.qm_claim.defect_cd | U39: 초안
A40: CustomerComplaint | B40: 고객클레임 | C40: CustomerComplaint | D40: 19 | E40: 클레임수량 | F40: ComplaintQuantity | G40: ComplaintQuantity | H40: 확장 | I40: float | J40: NUMERIC(18,6) | P40: 비대상 | R40: — 고객이 부적합으로 제기한 수량(기준단위) | S40: qms.qm_claim.claim_qty | U40: 초안
...

Sheet 관계목록
A1: No | B1: 자식 테이블 | C1: FK 컬럼 | D1: 부모 테이블 | E1: 부모 키 컬럼(UK) | F1: 관계 구분 | G1: 비고 | H1: FK 구분
A2: 1 | B2: StandardCost | C2: EnterpriseID | D2: Enterprise | E2: EnterpriseID | F2: 기본 속성 | H2: 물리
A3: 2 | B3: StandardCost | C3: EnterpriseID, SiteID | D3: Site | E3: EnterpriseID, SiteID | F3: 기본 속성 | H3: 물리
A4: 3 | B4: StandardCost | C4: EnterpriseID, PlantID | D4: Plant | E4: EnterpriseID, PlantID | F4: 기본 속성 | H4: 물리
A5: 4 | B5: StandardCost | C5: EnterpriseID, CreatorID | D5: Personnel | E5: EnterpriseID, PersonnelID | F5: 기본 속성 | H5: 물리
A6: 5 | B6: StandardCost | C6: EnterpriseID, ModifierID | D6: Personnel | E6: EnterpriseID, PersonnelID | F6: 기본 속성 | H6: 물리
A7: 6 | B7: StandardCost | C7: EnterpriseID, ItemID | D7: ItemMaster | E7: EnterpriseID, ItemID | F7: 명사 참조 | H7: 물리
A8: 7 | B8: StandardCost | C8: EnterpriseID, OperationID | D8: Operation | E8: EnterpriseID, OperationID | F8: 명사 참조 | H8: 물리
A9: 8 | B9: CustomerComplaint | C9: EnterpriseID | D9: Enterprise | E9: EnterpriseID | F9: 기본 속성 | H9: 물리
A10: 9 | B10: CustomerComplaint | C10: EnterpriseID, SiteID | D10: Site | E10: EnterpriseID, SiteID | F10: 기본 속성 | H10: 물리
A11: 10 | B11: CustomerComplaint | C11: EnterpriseID, PlantID | D11: Plant | E11: EnterpriseID, PlantID | F11: 기본 속성 | H11: 물리
A12: 11 | B12: CustomerComplaint | C12: EnterpriseID, CreatorID | D12: Personnel | E12: EnterpriseID, PersonnelID | F12: 기본 속성 | H12: 물리
A13: 12 | B13: CustomerComplaint | C13: EnterpriseID, ModifierID | D13: Personnel | E13: EnterpriseID, PersonnelID | F13: 기본 속성 | H13: 물리
... A37: 36 | B37: LotInventory | C37: EnterpriseID, LotID | D37: Lot | E37: EnterpriseID, LotID | F37: 명사 참조 | H37: 물리
A38: 37 | B38: SalesPlanExt | C38: EnterpriseID, SalesPlanID | D38: SalesPlan | E38: EnterpriseID, SalesPlanID | F38: 확장 대상(1:1) | G38: Core 행 1개당 확장 행 최대 1개 | H38: 물리
A39: 38 | B39: SalesPlanExt | C39: EnterpriseID, CustomerID | D39: CustomerPartyMaster | E39: EnterpriseID, CustomerID | F39: 명사 참조 | H39: 물리
A40: 39 | B40: SalesOrderLineExt | C40: EnterpriseID, SalesDocumentNumber, SalesDocumentSequence | D40: SalesOrderLine | E40: EnterpriseID, SalesDocumentNumber, SalesDocumentSequence | F40: 확장 대상(1:1) | G40: Core 행 1개당 확장 행 최대 1개 | H40: 물리
A41: 40 | B41: AvailableInventoryExt | C41: EnterpriseID, AvailableInventoryID | D41: AvailableInventory | E41: EnterpriseID, AvailableInventoryID | F41: 확장 대상(1:1) | G41: Core 행 1개당 확장 행 최대 1개 | H41: 물리
A42: 41 | B42: AvailableInventoryExt | C42: EnterpriseID, ProductionOrderID, ProductionOrderSequence | D42: ProductionOrder | E42: EnterpriseID, ProductionOrderID, ProductionOrderSequence | F42: 명사 참조 | H42: 물리
A43: 42 | B43: ProductionPerformanceExt | C43: EnterpriseID, ProductionPerformanceID, ProductionPerformanceSequence | D43: ProductionPerformance | E43: EnterpriseID, ProductionPerformanceID, ProductionPerformanceSequence | F43: 확장 대상(1:1) | G43: Core 행 1개당 확장 행 최대 1개 | H43: 물리
A44: 43 | B44: SupplierInspectionResultExt | C44: EnterpriseID, InspectionResultID | D44: SupplierInspectionResult | E44: EnterpriseID, InspectionResultID | F44: 확장 대상(1:1) | G44: Core 행 1개당 확장 행 최대 1개 | H44: 물리
A45: 44 | B45: SupplierInspectionResultExt | C45: EnterpriseID, GoodsReceiptID, GoodsReceiptSequence | D45: GoodsReceipt | E45: EnterpriseID, GoodsReceiptID, GoodsReceiptSequence | F45: 명사 참조 | H45: 물리
A46: 45 | B46: CorrectiveActionRequestExt | C46: EnterpriseID, CorrectiveActionRequestID | D46: CorrectiveActionRequest | E46: EnterpriseID, CorrectiveActionRequestID | F46: 확장 대상(1:1) | G46: Core 행 1개당 확장 행 최대 1개 | H46: 물리
A47: 46 | B47: EquipmentExt | C47: EnterpriseID, EquipmentID | D47: Equipment | E47: EnterpriseID, EquipmentID | F47: 확장 대상(1:1) | G47: Core 행 1개당 확장 행 최대 1개 | H47: 물리
A48: 47 | B48: EquipmentStateExt | C48: EnterpriseID, EquipmentStateID | D48: EquipmentState | E48: EnterpriseID, EquipmentStateID | F48: 확장 대상(1:1) | G48: Core 행 1개당 확장 행 최대 1개 | H48: 물리

Sheet 코드그룹목록
A1: No | B1: 업무영역 | C1: 공통코드그룹 (CommonCodeGroup) | D1: 그룹명 | E1: 코드체계 | F1: 상위 그룹 | G1: 그룹 설명 | H1: 사용 속성(영문) | I1: 사용 명사 | J1: 확장 구분 | K1: 상태
A2: 1 | B2: 판매관리 | C2: SalesPlanType | D2: 판매계획유형 | E2: 고정형 | G2: 판매계획의 유형: 수요예측과 판매계획을 구분 | H2: SalesPlanType | I2: SalesPlan(확장) | J2: 신규 그룹 | K2: 초안
A3: 2 | B3: 품질관리(확장) | C3: CustomerComplaintType | D3: 고객클레임유형 | E3: 고정형 | G3: 고객 클레임의 유형 | H3: CustomerComplaintType | I3: CustomerComplaint | J3: 신규 그룹 | K3: 초안
A4: 3 | B4: 품질관리(확장) | C4: CustomerComplaintStatusCode | D4: 고객클레임상태코드 | E4: 고정형 | G4: 고객 클레임 처리 상태 | H4: CustomerComplaintStatusCode | I4: CustomerComplaint | J4: 신규 그룹 | K4: 초안
A5: 4 | B5: 품질관리(확장) | C5: QualityCostClass | D5: 품질비용구분 | E5: 고정형 | G5: PAF 모델 품질비용 구분 | H5: QualityCostClass | I5: QualityCost | J5: 신규 그룹 | K5: 초안
A6: 5 | B6: 품질관리(확장) | C6: QualityCostItem | D6: 품질비용항목 | E6: 회사정의(계층) | F6: QualityCostClass | G6: 품질비용 세부 항목(상위: 품질비용구분) | H6: QualityCostItem | I6: QualityCost | J6: 신규 그룹 | K6: 초안
A7: 6 | B7: 품질관리(확장) | C7: DetectionLocationType | D7: 발견위치유형 | E7: 고정형 | G7: 부적합을 발견한 위치 | H7: DetectionLocationType | I7: CorrectiveActionRequest(확장) | J7: 신규 그룹 | K7: 초안
A8: 7 | B8: 생산관리(확장) | C8: EquipmentIdleReasonCode | D8: 대기사유코드 | E8: 회사정의 | G8: 설비 대기(IDLE) 사유 | H8: EquipmentIdleReasonCode | I8: EquipmentState(확장) | J8: 신규 그룹 | K8: 후보
A9: 8 | B9: 생산관리 | C9: DefectTypeDetailCode | D9: 불량유형상세코드 | E9: 회사정의(계층) | F9: DefectTypeCode | G9: 표준 그룹에 회사 하위 코드 추가 | H9: DefectTypeDetailCode | I9: ProductionPerformanceQuality 외 | J9: 표준 그룹 하위 확장 | K9: 초안

Sheet 공통코드
A1: No | B1: 업무영역 | C1: 공통코드그룹 (CommonCodeGroup) | D1: 그룹명 | E1: 공통코드식별자 (CommonCodeID) | F1: 공통코드명 (CommonCodeName) | G1: 영문명 | H1: 표시순번 (CommonCodeSequence) | I1: 사용여부 (UseIndicator) | J1: 상위공통코드그룹 (ParentCommonCodeGroup) | K1: 상위공통코드식별자 (ParentCommonCodeID) | L1: 설명 | M1: 출처구분 | N1: 회사 적용 (Y/N) | O1: 회사 코드값 | P1: 회사 코드명 | Q1: 비고(회사) | R1: 상태
A2: 1 | B2: 판매관리 | C2: SalesPlanType | D2: 판매계획유형 | E2: FCST | F2: 수요예측 | G2: Forecast | H2: 1 | I2: Y | L2: 고객 수요 예측치 | M2: 확장 | N2: Y | O2: FCST | P2: 수요예측 | R2: 초안
A3: 2 | B3: 판매관리 | C3: SalesPlanType | D3: 판매계획유형 | E3: PLAN | F3: 판매계획 | G3: Sales plan | H3: 2 | I3: Y | L3: 확정 판매 목표 | M3: 확장 | N3: Y | O3: PLAN | P3: 판매계획 | R3: 초안
A4: 3 | B4: 품질관리(확장) | C4: CustomerComplaintType | D4: 고객클레임유형 | E4: NC | F4: 고객 부적합 | G4: Nonconformance | H4: 1 | I4: Y | L4: 고객 입고검사·공정에서 발견한 부적합 | M4: 확장 | N4: Y | O4: NC | P4: 고객 부적합 | R4: 초안
A5: 4 | B5: 품질관리(확장) | C5: CustomerComplaintType | D5: 고객클레임유형 | E5: LS | F5: 고객 라인 중단 | G5: Line stop | H5: 2 | I5: Y | L5: 고객 조립 라인을 멈추게 한 부적합 | M5: 확장 | N5: Y | O5: LS | P5: 고객 라인 중단 | R5: 초안
A6: 5 | B6: 품질관리(확장) | C6: CustomerComplaintType | D6: 고객클레임유형 | E6: FR | F6: 필드 반송 | G6: Field return | H6: 3 | I6: Y | L6: 시장(필드)에서 반송된 제품 | M6: 확장 | N6: Y | O6: FR | P6: 필드 반송 | R6: 초안
A7: 6 | B7: 품질관리(확장) | C7: CustomerComplaintStatusCode | D7: 고객클레임상태코드 | E7: OPEN | F7: 접수 | G7: Open | H7: 1 | I7: Y | M7: 확장 | N7: Y | O7: OPEN | P7: 접수 | R7: 초안
A8: 7 | B8: 품질관리(확장) | C8: CustomerComplaintStatusCode | D8: 고객클레임상태코드 | E8: RESPONDED | F8: 대책 회신 | G8: Responded | H8: 2 | I8: Y | M8: 확장 | N8: Y | O8: RESP | P8: 회신 | R8: 초안
A9: 8 | B9: 품질관리(확장) | C9: CustomerComplaintStatusCode | D9: 고객클레임상태코드 | E9: CLOSED | F9: 종결 | G9: Closed | H9: 3 | I9: Y | M9: 확장 | N9: Y | O9: CLOSE | P9: 종결 | R9: 초안
A10: 9 | B10: 품질관리(확장) | C10: QualityCostClass | D10: 품질비용구분 | E10: P | F10: 예방비용 | G10: Prevention | H10: 1 | I10: Y | M10: 확장 | N10: Y | O10: P | P10: 예방비용 | R10: 초안
A11: 10 | B11: 품질관리(확장) | C11: QualityCostClass | D11: 품질비용구분 | E11: A | F11: 평가비용 | G11: Appraisal | H11: 2 | I11: Y | M11: 확장 | N11: Y | O11: A | P11: 평가비용 | R11: 초안
A12: 11 | B12: 품질관리(확장) | C12: QualityCostClass | D12: 품질비용구분 | E12: IF | F12: 내부실패비용 | G12: Internal failure | H12: 3 | I12: Y | M12: 확장 | N12: Y | O12: IF | P12: 내부실패비용 | R12: 초안
A13: 12 | B13: 품질관리(확장) | C13: QualityCostClass | D13: 품질비용구분 | E13: EF | F13: 외부실패비용 | G13: External failure | H13: 4 | I13: Y | M13: 확장 | N13: Y | O13: EF | P13: 외부실패비용 | R13: 초안
A14: 13 | B14: 품질관리(확장) | C14: QualityCostItem | D14: 품질비용항목 | E14: P-EDU | F14: 품질교육 | G14: Quality training | H14: 1 | I14: Y | J14: QualityCostClass | K14: P | M14: 확장 | N14: Y | O14: 품질교육 | P14: 품질교육 | R14: 초안
A15: 14 | B15: 품질관리(확장) | C15: QualityCostItem | D15: 품질비용항목 | E15: P-FMEA | F15: FMEA·예방활동 | G15: FMEA | H15: 2 | I15: Y | J15: QualityCostClass | K15: P | M15: 확장 | N15: Y | O15: FMEA·예방활동 | P15: FMEA·예방활동 | R15: 초안
A16: 15 | B16: 품질관리(확장) | C16: QualityCostItem | D16: 품질비용항목 | E16: A-IQC | F16: 수입검사 | G16: Incoming inspection | H16: 3 | I16: Y | J16: QualityCostClass | K16: A | M16: 확장 | N16: Y | O16: 수입검사 | P16: 수입검사 | R16: 초안
A17: 16 | B17: 품질관리(확장) | C17: QualityCostItem | D17: 품질비용항목 | E17: A-INSP | F17: 공정·출하검사 | G17: In-process inspection | H17: 4 | I17: Y | J17: QualityCostClass | K17: A | M17: 확장 | N17: Y | O17: 공정·출하검사 | P17: 공정·출하검사 | R17: 초안
A18: 17 | B18: 품질관리(확장) | C18: QualityCostItem | D18: 품질비용항목 | E18: A-CAL | F18: 계측기교정 | G18: Calibration | H18: 5 | I18: Y | J18: QualityCostClass | K18: A | M18: 확장 | N18: Y | O18: 계측기교정 | P18: 계측기교정 | R18: 초안
A19: 18 | B19: 품질관리(확장) | C19: QualityCostItem | D19: 품질비용항목 | E19: A-REL | F19: 신뢰성시험 | G19: Reliability test | H19: 6 | I19: Y | J19: QualityCostClass | K19: A | M19: 확장 | N19: Y | O19: 신뢰성시험 | P19: 신뢰성시험 | R19: 초안
A20: 19 | B20: 품질관리(확장) | C20: QualityCostItem | D20: 품질비용항목 | E20: IF-SCRAP | F20: 폐기 | G20: Scrap | H20: 7 | I20: Y | J20: QualityCostClass | K20: IF | M20: 확장 | N20: Y | O20: 폐기 | P20: 폐기 | R20: 초안
A21: 20 | B21: 품질관리(확장) | C21: QualityCostItem | D21: 품질비용항목 | E21: IF-REWORK | F21: 재작업 | G21: Rework | H21: 8 | I21: Y | J21: QualityCostClass | K21: IF | M21: 확장 | N21: Y | O21: 재작업 | P21: 재작업 | R21: 초안
A22: 21 | B22: 품질관리(확장) | C22: QualityCostItem | D22: 품질비용항목 | E22: EF-CLAIM | F22: 클레임 | G22: Claim | H22: 9 | I22: Y | J22: QualityCostClass | K22: EF | M22: 확장 | N22: Y | O22: 클레임 | P22: 클레임 | R22: 초안
A23: 22 | B23: 품질관리(확장) | C23: QualityCostItem | D23: 품질비용항목 | E23: EF-RTNFRT | F23: 반품운송 | G23: Return freight | H23: 10 | I23: Y | J23: QualityCostClass | K23: EF | M23: 확장 | N23: Y | O23: 반품운송 | P23: 반품운송 | R23: 초안
A24: 23 | B24: 품질관리(확장) | C24: DetectionLocationType | D24: 발견위치유형 | E24: IQC | F24: 수입검사 | G24: Incoming inspection | H24: 1 | I24: Y | M24: 확장 | N24: Y | O24: IQC | P24: 수입검사 | R24: 초안
A25: 24 | B25: 품질관리(확장) | C25: DetectionLocationType | D25: 발견위치유형 | E25: LINE | F25: 생산라인 | G25: Production line | H25: 2 | I25: Y | M25: 확장 | N25: Y | O25: LINE | P25: 라인 | R25: 초안
A26: 25 | B26: 품질관리(확장) | C26: DetectionLocationType | D26: 발견위치유형 | E26: CUST | F26: 고객 | G26: Customer | H26: 3 | I26: Y | M26: 확장 | N26: Y | O26: CUST | P26: 고객 | R26: 초안
A27: 26 | B27: 생산관리(확장) | C27: EquipmentIdleReasonCode | D27: 대기사유코드 | E27: NO_ORDER | F27: 작업 없음 | G27: No order | H27: 1 | I27: Y | M27: 확장 | N27: Y | R27: 후보
A28: 27 | B28: 생산관리(확장) | C28: EquipmentIdleReasonCode | D28: 대기사유코드 | E28: MAT_SHORT | F28: 자재 부족 | G28: Material shortage | H28: 2 | I28: Y | M28: 확장 | N28: Y | R28: 후보
A29: 28 | B29: 생산관리(확장) | C29: EquipmentIdleReasonCode | D29: 대기사유코드 | E29: QC_WAIT | F29: 검사 대기 | G29: Waiting QC | H29: 3 | I29: Y | M29: 확장 | N29: Y | R29: 후보
A30: 29 | B30: 생산관리(확장) | C30: EquipmentIdleReasonCode | D30: 대기사유코드 | E30: UPSTREAM | F30: 전공정 대기 | G30: Waiting upstream | H30: 4 | I30: Y | M30: 확장 | N30: Y | R30: 후보
A31: 30 | B31: 생산관리(확장) | C31: EquipmentIdleReasonCode | D31: 대기사유코드 | E31: ETC | F31: 기타 | G31: Other | H31: 5 | I31: Y | M31: 확장 | N31: Y | R31: 후보
A32: 31 | B32: 생산관리 | C32: DefectTypeDetailCode | D32: 불량유형상세코드 | E32: MAT-POR | F32: 기공 | G32: Porosity | H32: 101 | I32: Y | J32: DefectTypeCode | K32: MAT | L32: 주조 내부 기공(가스·수축) | M32: 표준 그룹 하위 확장 | N32: Y | O32: D-PORO | P32: 기공 | R32: 초안
A33: 32 | B33: 생산관리 | C33: DefectTypeDetailCode | D33: 불량유형상세코드 | E33: MAT-SHT | F33: 미성형 | G33: Short shot | H33: 102 | I33: Y | J33: DefectTypeCode | K33: MAT | L33: 주조 충전 부족 | M33: 표준 그룹 하위 확장 | N33: Y | O33: D-SHORT | P33: 미성형 | R33: 초안
A34: 33 | B34: 생산관리 | C34: DefectTypeDetailCode | D34: 불량유형상세코드 | E34: ASSY-SLD | F34: 납땜 불량 | G34: Soldering defect | H34: 103 | I34: Y | J34: DefectTypeCode | K34: ASSY | L34: PCB 납땜 불량 | M34: 표준 그룹 하위 확장 | N34: Y | O34: I-SOLDER | P34: 납땜 불량 | R34: 초안

Sheet 판정목록
A1: No | B1: 시나리오·KPI | C1: 원천(시스템.테이블.컬럼) | D1: 원천 의미 | E1: 판정 | F1: 표준·확장 대상 | G1: 근거 | H1: 처리 단계 | I1: 상태
A2: 1 | B2: SC05·SC06·SC07 / PR02·PR04·SC06 | C2: erp.tb_co_std_cost | D2: 월 표준원가(원가 요소) | E2: 확장 명사 | F2: StandardCost | G2: ③ 표준에 원가 명사 없음(BasePrice는 구매 단가) | H2: S2 | I2: 초안
A3: 2 | B3: SC05 / PR04 | C3: qms.qm_scrap.unit_cost | D3: 공정 단계 단위원가 | E3: 확장 명사 | F3: StandardCost.OperationID 단계 원가 | G3: ③ 공정 단계 누적원가 — StandardCost에 공정 차원으로 통합 | H3: S2 | I3: 초안
A4: 3 | B4: SC05·SC06 / PR04·QM06 | C4: qms.qm_scrap | D4: 불량 폐기 처리 | E4: 표준 매핑 | F4: GoodsIssue(폐기 수불) + ProductionPerformanceQuality | G4: ① 폐기 수량은 표준 수불·생산품질실적으로 표현, 금액은 StandardCost로 환산 | H4: S2 | I4: 초안
A5: 4 | B5: SC06 / QM01~03·QM07 | C5: qms.qm_claim | D5: 고객 클레임 | E5: 확장 명사 | F5: CustomerComplaint | G5: ③ 반품·사후서비스신청은 일부만 대응(회신 기한·클레임 유형·금액 없음) | H5: S2 | I5: 초안
A6: 5 | B6: SC06 / QM03 | C6: qms.qm_claim(claim_tp=FR) | D6: 필드 반송 수량 | E6: 표준 매핑 | F6: Return(ReturnType=SAL-DEF) | G6: ① 반송 실물은 표준 반품으로 함께 기록, 클레임과 LOT으로 연결 | H6: S2 | I6: 초안
A7: 6 | B7: SC06 | C7: qms.qm_claim.defect_cd | D7: 고객 불량 코드 C-* | E7: 코드 대응 | F7: DefectTypeDetailCode: C-LEAK→FUNC-LEK, C-NOISE→FUNC-NOI, C-CONN→FUNC-NOP, C-LABEL→PKG-LBL | G7: 표준 회사정의 코드로 대응 — 확장 불필요 | H7: S2 | I7: 초안
A8: 7 | B8: SC06 / QM04·PR05 | C8: qms.qm_qcost | D8: 품질비용 월 집계 | E8: 확장 명사 | F8: QualityCost | G8: ③ 표준에 품질비용 명사 없음 | H8: S2 | I8: 초안
A9: 8 | B9: SC07 / SC06·SC07·CS02 | C9: erp.tb_mm_stock_day | D9: 일 마감 재고 | E9: 확장 명사 | F9: InventorySnapshot | G9: ③ 표준 재고는 현재고(기준일 없음) — 식별 조합에 기준일을 더하면 별개 객체 | H9: S2 | I9: 초안
A10: 9 | B10: SC07 / SC09 | C10: erp.tb_mm_stock_lot | D10: 로트·입고일별 재고 | E10: 확장 명사 | F10: LotInventory | G10: ③ 표준 재고에 로트·입고일 없음 — 식별 단위가 달라 별개 객체 | H10: S2 | I10: 초안
A11: 10 | B11: SC07 / SC01·SC02 | C11: erp.tb_sd_plan.plan_tp, cust_cd, plan_ver | D11: 계획 유형·고객·버전 | E11: 확장 속성 | F11: SalesPlanExt.SalesPlanType·CustomerID·SalesPlanVersion | G11: ② 판매계획 명사에 속하나 표준 속성 없음 | H11: S2 | I11: 초안
A12: 11 | B12: SC07 / QM04 | C12: erp.tb_sd_so_d.unit_prc | D12: 판매단가 | E12: 확장 속성 | F12: SalesOrderLineExt.UnitPrice·CurrencyCode·SalesAmount | G12: ② 표준 수주라인에 단가 없음(UnitPrice는 표준 공유 속성 재사용) | H12: S2 | I12: 초안
A13: 12 | B13: SC07 / SC04 | C13: erp.tb_pp_mat_chk.avail_qty, req_qty | D13: 가용·소요 수량 | E13: 표준 매핑 | F13: AvailableInventory.AvailableInventoryQuantity, PriorDemandQuantity | G13: ① 표준 속성과 의미·타입 같음 | H13: S2 | I13: 초안
... A29: 28 | B29: SC02 | C29: erp.tb_pp_rcpt.src | D29: 적재 경로 표식(HIST·MES·MAN) | E29: 제외 | F29: — | G29: ④ 기술 컬럼 — 적재 이력은 audit에 기록 | H29: S3 | I29: 초안

Sheet 검토·승인
A1: 구분 | B1: 항목 | C1: 내용 | D1: 일자 | E1: 서명·비고
A2: 검사 | B2: ksxgen ext-sync 결과 | C2: 오류 0, 경고 0 — 확장 명사 5, 확장 속성 테이블 8, 확장 컬럼 73, 코드 그룹 8, 코드 33, 판정 28
A3: 승인 | B3: 도메인(PI) 컨설턴트
A4: 승인 | B4: 고객사 현업 검수자
A5: 승인 | B5: 온톨로지 엔지니어
A6: 승인 | B6: PM

Sheet DDL
A1: 테이블명 | B1: CREATE TABLE (PostgreSQL 참고, ext 스키마)
A2: StandardCost | B2: CREATE TABLE ext."StandardCost" ( -- 표준원가 (확장 명사) "StandardCostSequenceNo" BIGINT GENERATED BY DEFAULT AS IDENTITY, -- 표준원가 일련번호(PK) "EnterpriseID" VARCHAR(50) NOT NULL, -- 회사식별자 "SiteID" VARCHAR(50) NOT NULL, -- 사업장식별자 "PlantID" VARCHAR(50) NOT NULL, -- 공장식별자 "CreatorID" VARCHAR(50), -- 등록자식별자 "CreationDateTime" TIMESTAMP, -- 등록일시 "ModifierID" VARCHAR(50), -- 수정자식별자 "ModificationDateTime" TIMESTAMP, -- 수정일시 "Note" VARCHAR(1000), -- 비고 "StandardCostID" VARCHAR(50) NOT NULL, -- 표준원가식별자 "ItemID" VARCHAR(50) NOT NULL, -- 품목식별자 "OperationID" VARCHAR(50), -- 공정식별자 "CostPeriodStartDate" DATE NOT NULL, -- 원가기간시작일 "CostPeriodEndDate" DATE, -- 원가기간종료일 "StandardCostAmount" NUMERIC(18,6) NOT NULL, -- 표준원가 "MaterialCostAmount" NUMERIC(18,6), -- 재료비 "LaborCostAmount" NUMERIC(18,6), -- 노무비 "OverheadCostAmount" NUMERIC(18,6), -- 경비 "CurrencyCode" VARCHAR(30), -- 환종코드 "ItemUOMCode" VARCHAR(30), -- 기준단위코드 CONSTRAINT "PK_StandardCost" PRIMARY KEY ("StandardCostSequenceNo"), CONSTRAINT "UK_StandardCost" UNIQUE ("EnterpriseID", "StandardCostID") );
A3: CustomerComplaint | B3: CREATE TABLE ext."CustomerComplaint" ( -- 고객클레임 (확장 명사) "CustomerComplaintSequenceNo" BIGINT GENERATED BY DEFAULT AS IDENTITY, -- 고객클레임 일련번호(PK) "EnterpriseID" VARCHAR(50) NOT NULL, -- 회사식별자 "SiteID" VARCHAR(50) NOT NULL, -- 사업장식별자 "PlantID" VARCHAR(50) NOT NULL, -- 공장식별자 "CreatorID" VARCHAR(50), -- 등록자식별자 "CreationDateTime" TIMESTAMP, -- 등록일시 "ModifierID" VARCHAR(50), -- 수정자식별자 "ModificationDateTime" TIMESTAMP, -- 수정일시 "Note" VARCHAR(1000), -- 비고 "CustomerComplaintID" VARCHAR(50) NOT NULL, -- 고객클레임식별자 "CustomerID" VARCHAR(50) NOT NULL, -- 고객사식별자 "ItemID" VARCHAR(50), -- 품목식별자 "LotID" VARCHAR(50), -- 로트식별자 "CustomerComplaintType" VARCHAR(30) NOT NULL, -- 고객클레임유형 "OccurrenceDate" DATE, -- 발생일 "ComplaintReceiptDate" DATE, -- 접수일 "DefectTypeCode" VARCHAR(30), -- 불량유형코드 "DefectTypeDetailCode" VARCHAR(30), -- 불량유형상세코드 "ComplaintQuantity" NUMERIC(18,6), -- 클레임수량 "ItemUOMCode" VARCHAR(30), -- 기준단위코드 "ResponseDueDate" DATE NOT NULL, -- 대책회신기한 "ResponseDate" DATE, -- 대책회신일 "CloseDate" DATE, -- 종결일 "CustomerComplaintStatusCode" VARCHAR(30), -- 고객클레임상태코드 "ComplaintAmount" NUMERIC(18,6), -- 클레임금액 "CurrencyCode" VARCHAR(30), -- 환종코드 "CauseOperationID" VARCHAR(50), -- 원인공정식별자 "ComplaintDescription" VARCHAR(255), -- 클레임내용 CONSTRAINT "PK_CustomerComplaint" PRIMARY KEY ("CustomerComplaintSequenceNo"), CONSTRAINT "UK_CustomerComplaint" UNIQUE ("EnterpriseID", "CustomerComplaintID") );
A4: QualityCost | B4: CREATE TABLE ext."QualityCost" ( -- 품질비용 (확장 명사) "QualityCostSequenceNo" BIGINT GENERATED BY DEFAULT AS IDENTITY, -- 품질비용 일련번호(PK) "EnterpriseID" VARCHAR(50) NOT NULL, -- 회사식별자 "SiteID" VARCHAR(50) NOT NULL, -- 사업장식별자 "PlantID" VARCHAR(50) NOT NULL, -- 공장식별자 "CreatorID" VARCHAR(50), -- 등록자식별자 "CreationDateTime" TIMESTAMP, -- 등록일시 "ModifierID" VARCHAR(50), -- 수정자식별자 "ModificationDateTime" TIMESTAMP, -- 수정일시 "Note" VARCHAR(1000), -- 비고 "QualityCostID" VARCHAR(50) NOT NULL, -- 품질비용식별자 "CostPeriodStartDate" DATE NOT NULL, -- 원가기간시작일 "CostPeriodEndDate" DATE, -- 원가기간종료일 "QualityCostClass" VARCHAR(30) NOT NULL, -- 품질비용구분 "QualityCostItem" VARCHAR(30) NOT NULL, -- 품질비용항목 "QualityCostAmount" NUMERIC(18,6) NOT NULL, -- 품질비용금액 "CurrencyCode" VARCHAR(30), -- 환종코드 "SourceDocumentReference" VARCHAR(255), -- 근거문서 CONSTRAINT "PK_QualityCost" PRIMARY KEY ("QualityCostSequenceNo"), CONSTRAINT "UK_QualityCost" UNIQUE ("EnterpriseID", "QualityCostID") );
A5: InventorySnapshot | B5: CREATE TABLE ext."InventorySnapshot" ( -- 일별재고 (확장 명사) "InventorySnapshotSequenceNo" BIGINT GENERATED BY DEFAULT AS IDENTITY, -- 일별재고 일련번호(PK) "EnterpriseID" VARCHAR(50) NOT NULL, -- 회사식별자 "SiteID" VARCHAR(50) NOT NULL, -- 사업장식별자 "PlantID" VARCHAR(50) NOT NULL, -- 공장식별자 "CreatorID" VARCHAR(50), -- 등록자식별자 "CreationDateTime" TIMESTAMP, -- 등록일시 "ModifierID" VARCHAR(50), -- 수정자식별자 "ModificationDateTime" TIMESTAMP, -- 수정일시 "Note" VARCHAR(1000), -- 비고 "InventorySnapshotDate" DATE NOT NULL, -- 재고기준일 "WarehouseID" VARCHAR(50) NOT NULL, -- 창고식별자 "ItemID" VARCHAR(50) NOT NULL, -- 품목식별자 "InventoryQuantity" NUMERIC(18,6), -- 현재고수량 "ItemUOMCode" VARCHAR(30), -- 기준단위코드 CONSTRAINT "PK_InventorySnapshot" PRIMARY KEY ("InventorySnapshotSequenceNo"), CONSTRAINT "UK_InventorySnapshot" UNIQUE ("EnterpriseID", "InventorySnapshotDate", "WarehouseID", "ItemID") );
A6: LotInventory | B6: CREATE TABLE ext."LotInventory" ( -- 로트별재고 (확장 명사) "LotInventorySequenceNo" BIGINT GENERATED BY DEFAULT AS IDENTITY, -- 로트별재고 일련번호(PK) "EnterpriseID" VARCHAR(50) NOT NULL, -- 회사식별자 "SiteID" VARCHAR(50) NOT NULL, -- 사업장식별자 "PlantID" VARCHAR(50) NOT NULL, -- 공장식별자 "CreatorID" VARCHAR(50), -- 등록자식별자 "CreationDateTime" TIMESTAMP, -- 등록일시 "ModifierID" VARCHAR(50), -- 수정자식별자 "ModificationDateTime" TIMESTAMP, -- 수정일시 "Note" VARCHAR(1000), -- 비고 "WarehouseID" VARCHAR(50) NOT NULL, -- 창고식별자 "ItemID" VARCHAR(50) NOT NULL, -- 품목식별자 "LotID" VARCHAR(50) NOT NULL, -- 로트식별자 "GoodsReceiptDate" DATE NOT NULL, -- 입고처리일 "InventoryQuantity" NUMERIC(18,6), -- 현재고수량 "ItemUOMCode" VARCHAR(30), -- 기준단위코드 CONSTRAINT "PK_LotInventory" PRIMARY KEY ("LotInventorySequenceNo"), CONSTRAINT "UK_LotInventory" UNIQUE ("EnterpriseID", "WarehouseID", "ItemID", "LotID") );
A7: SalesPlanExt | B7: CREATE TABLE ext."SalesPlanExt" ( -- 판매계획 확장 (확장 속성 → SalesPlan) "SalesPlanExtSequenceNo" BIGINT GENERATED BY DEFAULT AS IDENTITY, -- 판매계획 확장 일련번호(PK) "EnterpriseID" VARCHAR(50) NOT NULL, -- 회사식별자 "SalesPlanID" VARCHAR(50) NOT NULL, -- 판매계획식별자 "SalesPlanType" VARCHAR(30) NOT NULL, -- 판매계획유형 "CustomerID" VARCHAR(50), -- 고객사식별자 "SalesPlanVersion" INTEGER, -- 판매계획버전 CONSTRAINT "PK_SalesPlanExt" PRIMARY KEY ("SalesPlanExtSequenceNo"), CONSTRAINT "UK_SalesPlanExt" UNIQUE ("EnterpriseID", "SalesPlanID") );
A8: SalesOrderLineExt | B8: CREATE TABLE ext."SalesOrderLineExt" ( -- 수주오더라인 확장 (확장 속성 → SalesOrderLine) "SalesOrderLineExtSequenceNo" BIGINT GENERATED BY DEFAULT AS IDENTITY, -- 수주오더라인 확장 일련번호(PK) "EnterpriseID" VARCHAR(50) NOT NULL, -- 회사식별자 "SalesDocumentNumber" VARCHAR(50) NOT NULL, -- 수주문서번호 "SalesDocumentSequence" INTEGER NOT NULL, -- 수주문서순번 "UnitPrice" NUMERIC(18,6), -- 단가 "CurrencyCode" VARCHAR(30), -- 환종코드 "SalesAmount" NUMERIC(18,6), -- 판매금액 CONSTRAINT "PK_SalesOrderLineExt" PRIMARY KEY ("SalesOrderLineExtSequenceNo"), CONSTRAINT "UK_SalesOrderLineExt" UNIQUE ("EnterpriseID", "SalesDocumentNumber", "SalesDocumentSequence") );
A9: AvailableInventoryExt | B9: CREATE TABLE ext."AvailableInventoryExt" ( -- 가용재고 확장 (확장 속성 → AvailableInventory) "AvailableInventoryExtSequenceNo" BIGINT GENERATED BY DEFAULT AS IDENTITY, -- 가용재고 확장 일련번호(PK) "EnterpriseID" VARCHAR(50) NOT NULL, -- 회사식별자 "AvailableInventoryID" VARCHAR(50) NOT NULL, -- 가용재고식별자 "ProductionOrderID" VARCHAR(50), -- 생산지시식별자 "ProductionOrderSequence" INTEGER, -- 생산지시순번 "AvailabilityCheckDateTime" TIMESTAMP, -- 점검일시 "ShortageQuantity" NUMERIC(18,6), -- 부족수량 CONSTRAINT "PK_AvailableInventoryExt" PRIMARY KEY ("AvailableInventoryExtSequenceNo"), CONSTRAINT "UK_AvailableInventoryExt" UNIQUE ("EnterpriseID", "AvailableInventoryID") );
A10: ProductionPerformanceExt | B10: CREATE TABLE ext."ProductionPerformanceExt" ( -- 생산실적 확장 (확장 속성 → ProductionPerformance) "ProductionPerformanceExtSequenceNo" BIGINT GENERATED BY DEFAULT AS IDENTITY, -- 생산실적 확장 일련번호(PK) "EnterpriseID" VARCHAR(50) NOT NULL, -- 회사식별자 "ProductionPerformanceID" VARCHAR(50) NOT NULL, -- 생산실적식별자 "ProductionPerformanceSequence" INTEGER NOT NULL, -- 생산실적순번 "InspectionResult" VARCHAR(30), -- 검사결과 "InspectionQuantity" NUMERIC(18,6), -- 검사수량 CONSTRAINT "PK_ProductionPerformanceExt" PRIMARY KEY ("ProductionPerformanceExtSequenceNo"), CONSTRAINT "UK_ProductionPerformanceExt" UNIQUE ("EnterpriseID", "ProductionPerformanceID", "ProductionPerformanceSequence") );
A11: SupplierInspectionResultExt | B11: CREATE TABLE ext."SupplierInspectionResultExt" ( -- 협력업체품질검사결과 확장 (확장 속성 → SupplierInspectionResult) "SupplierInspectionResultExtSequenceNo" BIGINT GENERATED BY DEFAULT AS IDENTITY, -- 협력업체품질검사결과 확장 일련번호(PK) "EnterpriseID" VARCHAR(50) NOT NULL, -- 회사식별자 "InspectionResultID" VARCHAR(50) NOT NULL, -- 검사결과식별자 "GoodsReceiptID" VARCHAR(50), -- 입고식별자 "GoodsReceiptSequence" INTEGER, -- 입고순번 "DefectQuantity" NUMERIC(18,6), -- 불량수량 "DefectTypeCode" VARCHAR(30), -- 불량유형코드 "DefectTypeDetailCode" VARCHAR(30), -- 불량유형상세코드 CONSTRAINT "PK_SupplierInspectionResultExt" PRIMARY KEY ("SupplierInspectionResultExtSequenceNo"), CONSTRAINT "UK_SupplierInspectionResultExt" UNIQUE ("EnterpriseID", "InspectionResultID") );
A12: CorrectiveActionRequestExt | B12: CREATE TABLE ext."CorrectiveActionRequestExt" ( -- 시정조치요청 확장 (확장 속성 → CorrectiveActionRequest) "CorrectiveActionRequestExtSequenceNo" BIGINT GENERATED BY DEFAULT AS IDENTITY, -- 시정조치요청 확장 일련번호(PK) "EnterpriseID" VARCHAR(50) NOT NULL, -- 회사식별자 "CorrectiveActionRequestID" VARCHAR(50) NOT NULL, -- 시정조치요청식별자 "DetectionLocationType" VARCHAR(30) NOT NULL, -- 발견위치유형 "DefectQuantity" NUMERIC(18,6), -- 불량수량 "DefectTypeCode" VARCHAR(30), -- 불량유형코드 "DefectTypeDetailCode" VARCHAR(30), -- 불량유형상세코드 "CorrectiveActionDueDate" DATE, -- 시정조치기한 CONSTRAINT "PK_CorrectiveActionRequestExt" PRIMARY KEY ("CorrectiveActionRequestExtSequenceNo"), CONSTRAINT "UK_CorrectiveActionRequestExt" UNIQUE ("EnterpriseID", "CorrectiveActionRequestID") );
... A15: (물리 FK) | B15: ALTER TABLE ext."StandardCost" ADD CONSTRAINT "FK_StandardCost_01" FOREIGN KEY ("EnterpriseID") REFERENCES ksx."Enterprise" ("EnterpriseID") DEFERRABLE INITIALLY IMMEDIATE; ALTER TABLE ext."StandardCost" ADD CONSTRAINT "FK_StandardCost_02" FOREIGN KEY ("EnterpriseID", "SiteID") REFERENCES ksx."Site" ("EnterpriseID", "SiteID") DEFERRABLE INITIALLY IMMEDIATE; ALTER TABLE ext."StandardCost" ADD CONSTRAINT "FK_StandardCost_03" FOREIGN KEY ("EnterpriseID", "PlantID") REFERENCES ksx."Plant" ("EnterpriseID", "PlantID") DEFERRABLE INITIALLY IMMEDIATE; ALTER TABLE ext."StandardCost" ADD CONSTRAINT "FK_StandardCost_04" FOREIGN KEY ("EnterpriseID", "CreatorID") REFERENCES ksx."Personnel" ("EnterpriseID", "PersonnelID") DEFERRABLE INITIALLY IMMEDIATE; ALTER TABLE ext."StandardCost" ADD CONSTRAINT "FK_StandardCost_05" FOREIGN KEY ("EnterpriseID", "ModifierID") REFERENCES ksx."Personnel" ("EnterpriseID", "PersonnelID") DEFERRABLE INITIALLY IMMEDIATE; ALTER TABLE ext."StandardCost" ADD CONSTRAINT "FK_StandardCost_06" FOREIGN KEY ("EnterpriseID", "ItemID") REFERENCES ksx."ItemMaster" ("EnterpriseID", "ItemID") DEFERRABLE INITIALLY IMMEDIATE; ALTER TABLE ext."StandardCost" ADD CONSTRAINT "FK_StandardCost_07" FOREIGN KEY ("EnterpriseID", "OperationID") REFERENCES ksx."Operation" ("EnterpriseID", "OperationID") DEFERRABLE INITIALLY IMMEDIATE; ALTER TABLE ext."CustomerComplaint" ADD CONSTRAINT "FK_CustomerComplaint_01" FOREIGN KEY ("EnterpriseID") REFERENCES ksx."Enterprise" ("EnterpriseID") DEFERRABLE INITIALLY IMMEDIATE; ALTER TABLE ext."CustomerComplaint" ADD CONSTRAINT "FK_CustomerComplaint_02" FOREIGN KEY ("EnterpriseID", "SiteID") REFERENCES ksx."Site" ("EnterpriseID", "SiteID") DEFERRABLE INITIALLY IMMEDIATE; ALTER TABLE ext."CustomerComplaint" ADD CONSTRAINT "FK_CustomerComplaint_03" FOREIGN KEY ("EnterpriseID", "PlantID") REFERENCES ksx."Plant" ("EnterpriseID", "PlantID") DEFERRABLE INITIALLY IMMEDIATE; ALTER TABLE ext."CustomerComplaint" ADD CONSTRAINT "FK_CustomerComplaint_04" FOREIGN KEY ("EnterpriseID", "CreatorID") REFERENCES ksx."Personnel" ("EnterpriseID", "PersonnelID") DEFERRABLE INITIALLY IMMEDIATE; ALTER TABLE ext."CustomerComplaint" ADD CONSTRAINT "FK_CustomerComplaint_05" FOREIGN KEY ("EnterpriseID", "ModifierID") REFERENCES ksx."Personnel" ("EnterpriseID", "PersonnelID") DEFERRABLE INITIALLY IMMEDIATE; ALTER TABLE ext."CustomerComplaint" ADD CONSTRAINT "FK_CustomerComplaint_06" FOREIGN KEY ("EnterpriseID", "CustomerID") REFERENCES ksx."CustomerPartyMaster" ("EnterpriseID", "CustomerID") DEFERRABLE INITIALLY IMMEDIATE; ALTER TABLE ext."CustomerComplaint" ADD CONSTRAINT "FK_CustomerComplaint_07" FOREIGN KEY ("EnterpriseID", "ItemID") REFERENCES ksx."ItemMaster" ("EnterpriseID", "ItemID") DEFERRABLE INITIALLY IMMEDIATE; ALTER TABLE ext."CustomerComplaint" ADD CONSTRAINT "FK_CustomerComplaint_08" FOREIGN KEY ("EnterpriseID", "LotID") REFERENCES ksx."Lot" ("EnterpriseID", "LotID") DEFERRABLE INITIALLY IMMEDIATE; ALTER TABLE ext."CustomerComplaint" ADD CONSTRAINT "FK_CustomerComplaint_09" FOREIGN KEY ("EnterpriseID", "CauseOperationID") REFERENCES ksx."Operation" ("EnterpriseID", "OperationID") DEFERRABLE INITIALLY IMMEDIATE; ALTER TABLE ext."QualityCost" ADD CONSTRAINT "FK_QualityCost_01" FOREIGN KEY ("EnterpriseID") REFERENCES ksx."Enterprise" ("EnterpriseID") DEFERRABLE INITIALLY IMMEDIATE; ALTER TABLE ext."QualityCost" ADD CONSTRAINT "FK_QualityCost_02" FOREIGN KEY ("EnterpriseID", "SiteID") REFERENCES ksx."Site" ("EnterpriseID", "SiteID") DEFERRABLE INITIALLY IMMEDIATE; ALTER TABLE ext."QualityCost" ADD CONSTRAINT "FK_QualityCost_03" FOREIGN KEY ("EnterpriseID", "PlantID") REFERENCES ksx."Plant" ("EnterpriseID", "PlantID") DEFERRABLE INITIALLY IMMEDIATE; ALTER TABLE ext."QualityCost" ADD CONSTRAINT "FK_QualityCost_04" FOREIGN KEY ("EnterpriseID", "CreatorID") REFERENCES ksx."Personnel" ("EnterpriseID", "PersonnelID") DEFERRABLE INITIALLY IMMEDIATE; ALTER TABLE ext."QualityCost" ADD CONSTRAINT "FK_QualityCost_05" FOREIGN KEY ("EnterpriseID", "ModifierID") REFERENCES ksx."Personnel" ("EnterpriseID", "PersonnelID") DEFERRABLE INITIALLY IMMEDIATE; ALTER TABLE ext."InventorySnapshot" ADD CONSTRAINT "FK_InventorySnapshot_01" FOREIGN KEY ("EnterpriseID") REFERENCES ksx."Enterprise" ("EnterpriseID") DEFERRABLE INITIALLY IMMEDIATE; ALTER TABLE ext."InventorySnapshot" ADD CONSTRAINT "FK_InventorySnapshot_02" FOREIGN KEY ("EnterpriseID", "SiteID") REFERENCES ksx."Site" ("EnterpriseID", "SiteID") DEFERRABLE INITIALLY IMMEDIATE; ALTER TABLE ext."InventorySnapshot" ADD CONSTRAINT "FK_InventorySnapshot_03" FOREIGN KEY ("EnterpriseID", "PlantID") REFERENCES ksx."Plant" ("EnterpriseID", "PlantID") DEFERRABLE INITIALLY IMMEDIATE; ALTER TABLE ext."InventorySnapshot" ADD CONSTRAINT "FK_InventorySnapshot_04" FOREIGN KEY ("EnterpriseID", "CreatorID") REFERENCES ksx."Personnel" ("EnterpriseID", "PersonnelID") DEFERRABLE INITIALLY IMMEDIATE; ALTER TABLE ext."InventorySnapshot" ADD CONSTRAINT "FK_InventorySnapshot_05" FOREIGN KEY ("EnterpriseID", "ModifierID") REFERENCES ksx."Personnel" ("EnterpriseID", "PersonnelID") DEFERRABLE INITIALLY IMMEDIATE; ALTER TABLE ext."InventorySnapshot" ADD CONSTRAINT "FK_InventorySnapshot_06" FOREIGN KEY ("EnterpriseID", "WarehouseID") REFERENCES ksx."WarehouseLocationHeader" ("EnterpriseID", "WarehouseID") DEFERRABLE INITIALLY IMMEDIATE; ALTER TABLE ext."InventorySnapshot" ADD CONSTRAINT "FK_InventorySnapshot_07" FOREIGN KEY ("EnterpriseID", "ItemID") REFERENCES ksx."ItemMaster" ("EnterpriseID", "ItemID") DEFERRABLE INITIALLY IMMEDIATE; ALTER TABLE ext."LotInventory" ADD CONSTRAINT "FK_LotInventory_01" FOREIGN KEY ("EnterpriseID") REFERENCES ksx."Enterprise" ("EnterpriseID") DEFERRABLE INITIALLY IMMEDIATE; ALTER TABLE ext."LotInventory" ADD CONSTRAINT "FK_LotInventory_02" FOREIGN KEY ("EnterpriseID", "SiteID") REFERENCES ksx."Site" ("EnterpriseID", "SiteID") DEFERRABLE INITIALLY IMMEDIATE; ALTER TABLE ext."LotInventory" ADD CONSTRAINT "FK_LotInventory_03" FOREIGN KEY ("EnterpriseID", "PlantID") REFERENCES ksx."Plant" ("EnterpriseID", "PlantID") DEFERRABLE INITIALLY IMMEDIATE; ALTER TABLE ext."LotInventory" ADD CONSTRAINT "FK_LotInventory_04" FOREIGN KEY ("EnterpriseID", "CreatorID") REFERENCES ksx."Personnel" ("EnterpriseID", "PersonnelID") DEFERRABLE INITIALLY IMMEDIATE; ALTER TABLE ext."LotInventory" ADD CONSTRAINT "FK_LotInventory_05" FOREIGN KEY ("EnterpriseID", "ModifierID") REFERENCES ksx."Personnel" ("EnterpriseID", "PersonnelID") DEFERRABLE INITIALLY IMMEDIATE; ALTER TABLE ext."LotInventory" ADD CONSTRAINT "FK_LotInventory_06" FOREIGN KEY ("EnterpriseID", "WarehouseID") REFERENCES ksx."WarehouseLocationHeader" ("EnterpriseID", "WarehouseID") DEFERRABLE INITIALLY IMMEDIATE; ALTER TABLE ext."LotInventory" ADD CONSTRAINT "FK_LotInventory_07" FOREIGN KEY ("EnterpriseID", "ItemID") REFERENCES ksx."ItemMaster" ("EnterpriseID", "ItemID") DEFERRABLE INITIALLY IMMEDIATE; ALTER TABLE ext."LotInventory" ADD CONSTRAINT "FK_LotInventory_08" FOREIGN KEY ("EnterpriseID", "LotID") REFERENCES ksx."Lot" ("EnterpriseID", "LotID") DEFERRABLE INITIALLY IMMEDIATE; ALTER TABLE ext."SalesPlanExt" ADD CONSTRAINT "FK_SalesPlanExt_01" FOREIGN KEY ("EnterpriseID", "SalesPlanID") REFERENCES ksx."SalesPlan" ("EnterpriseID", "SalesPlanID") DEFERRABLE INITIALLY IMMEDIATE; ALTER TABLE ext."SalesPlanExt" ADD CONSTRAINT "FK_SalesPlanExt_02" FOREIGN KEY ("EnterpriseID", "CustomerID") REFERENCES ksx."CustomerPartyMaster" ("EnterpriseID", "CustomerID") DEFERRABLE INITIALLY IMMEDIATE; ALTER TABLE ext."SalesOrderLineExt" ADD CONSTRAINT "FK_SalesOrderLineExt_01" FOREIGN KEY ("EnterpriseID", "SalesDocumentNumber", "SalesDocumentSequence") REFERENCES ksx."SalesOrderLine" ("EnterpriseID", "SalesDocumentNumber", "SalesDocumentSequence") DEFERRABLE INITIALLY IMMEDIATE; ALTER TABLE ext."AvailableInventoryExt" ADD CONSTRAINT "FK_AvailableInventoryExt_01" FOREIGN KEY ("EnterpriseID", "AvailableInventoryID") REFERENCES ksx."AvailableInventory" ("EnterpriseID", "AvailableInventoryID") DEFERRABLE INITIALLY IMMEDIATE; ALTER TABLE ext."AvailableInventoryExt" ADD CONSTRAINT "FK_AvailableInventoryExt_02" FOREIGN KEY ("EnterpriseID", "ProductionOrderID", "ProductionOrderSequence") REFERENCES ksx."ProductionOrder" ("EnterpriseID", "ProductionOrderID", "ProductionOrderSequence") DEFERRABLE INITIALLY IMMEDIATE; ALTER TABLE ext."ProductionPerformanceExt" ADD CONSTRAINT "FK_ProductionPerformanceExt_01" FOREIGN KEY ("EnterpriseID", "ProductionPerformanceID", "ProductionPerformanceSequence") REFERENCES ksx."ProductionPerformance" ("EnterpriseID", "ProductionPerformanceID", "ProductionPerformanceSequence") DEFERRABLE INITIALLY IMMEDIATE; ALTER TABLE ext."SupplierInspectionResultExt" ADD CONSTRAINT "FK_SupplierInspectionResultExt_01" FOREIGN KEY ("EnterpriseID", "InspectionResultID") REFERENCES ksx."SupplierInspectionResult" ("EnterpriseID", "InspectionResultID") DEFERRABLE INITIALLY IMMEDIATE; ALTER TABLE ext."SupplierInspectionResultExt" ADD CONSTRAINT "FK_SupplierInspectionResultExt_02" FOREIGN KEY ("EnterpriseID", "GoodsReceiptID", "GoodsReceiptSequence") REFERENCES ksx."GoodsReceipt" ("EnterpriseID", "GoodsReceiptID", "GoodsReceiptSequence") DEFERRABLE INITIALLY IMMEDIATE; ALTER TABLE ext."CorrectiveActionRequestExt" ADD CONSTRAINT "FK_CorrectiveActionRequestExt_01" FOREIGN KEY ("EnterpriseID", "CorrectiveActionRequestID") REFERENCES ksx."CorrectiveActionRequest" ("EnterpriseID", "CorrectiveActionRequestID") DEFERRABLE INITIALLY IMMEDIATE; ALTER TABLE ext."EquipmentExt" ADD CONSTRAINT "FK_EquipmentExt_01" FOREIGN KEY ("EnterpriseID", "EquipmentID") REFERENCES ksx."Equipment" ("EnterpriseID", "EquipmentID") DEFERRABLE INITIALLY IMMEDIATE; ALTER TABLE ext."EquipmentStateExt" ADD CONSTRAINT "FK_EquipmentStateExt_01" FOREIGN KEY ("EnterpriseID", "EquipmentStateID") REFERENCES ksx."EquipmentState" ("EnterpriseID", "EquipmentStateID") DEFERRABLE INITIALLY IMMEDIATE;
